<?xml version="1.0" ?>
<!--
 * @Author: HencyCHEN
 * @Date: 2025-05-15 01:27:03
 * @LastEditTime: 2025-05-15 02:21:56
 * @LastEditors: HencyCHEN
 * @Description: 
 * @FilePath: /crt_ctag2f90c_gripper/README.md
 * @Email: hengxiangchen428@gamil.com
 * 可以输入预定的版权声明、个性签名、空行等
-->
<!-- =================================================================================== -->
<!-- |    This document was autogenerated by xacro from all.xacro                      | -->
<!-- |    EDITING THIS FILE BY HAND IS NOT RECOMMENDED                                 | -->
<!-- =================================================================================== -->
<robot name="full_model">
    <link name="world" />
    <link name="crt_base_link">
        <inertial>
            <origin rpy="0 0 0" xyz="3.45207417426861E-05 -0.000141443719270944 0.0415526970475172" />
            <mass value="0.310447980489903" />
            <inertia ixx="0.000404388005636034" ixy="-6.8589621466727E-08" ixz="5.84928727366459E-08" iyy="0.000296494720930083" iyz="-1.79342738400452E-07" izz="0.000212447969282029" />
        </inertial>
        <visual>
            <origin rpy="0 0 0" xyz="0 0 0" />
            <geometry>
                <mesh filename="package://crt_ctag2f90c_gripper_visualization/meshes/crt_base_link.STL" />
            </geometry>
            <material name="">
                <color rgba="0.976470588235294 0.866666666666667 0.784313725490196 1" />
            </material>
        </visual>
        <collision>
            <origin rpy="0 0 0" xyz="0 0 0" />
            <geometry>
                <!-- <mesh filename="package://crt_ctag2f90c_gripper_visualization/meshes/crt_base_link.STL" /> -->
            </geometry>
        </collision>
    </link>
    <joint name="world2crt_base_link" type="fixed">
        <origin xyz="0 0 0" rpy="0 0 0" />
        <parent link="world" />
        <child link="crt_base_link" />
    </joint>
    <link name="Left_1_Link">
        <inertial>
            <origin rpy="0 0 0" xyz="-1.28088127539536E-18 0.0252734640095115 -0.00214040614650292" />
            <mass value="0.0129014357535444" />
            <inertia ixx="3.35976482443235E-06" ixy="-3.3181849198807E-25" ixz="-3.35726667613063E-23" iyy="1.65185846940368E-07" iyz="2.63476012977044E-07" izz="3.25394125032869E-06" />
        </inertial>
        <visual>
            <origin rpy="0 0 0" xyz="0 0 0" />
            <geometry>
                <mesh filename="package://crt_ctag2f90c_gripper_visualization/meshes/Left_1_Link.STL" />
            </geometry>
            <material name="">
                <color rgba="0.976470588235294 0.866666666666667 0.784313725490196 1" />
            </material>
        </visual>
        <collision>
            <origin rpy="0 0 0" xyz="0 0 0" />
            <geometry>
                <mesh filename="package://crt_ctag2f90c_gripper_visualization/meshes/Left_1_Link.STL" />
            </geometry>
        </collision>
    </link>
    <joint name="Left_1_Joint" type="revolute">
        <origin rpy="1.5708 0 0" xyz="0 -0.030141 0.090147" />
        <parent link="crt_base_link" />
        <child link="Left_1_Link" />
        <axis xyz="-1 0 0" />
        <limit effort="2" lower="-0.8" upper="-0.1" velocity="1000" />
    </joint>
    <link name="Left_in_Link">
        <inertial>
            <origin rpy="0 0 0" xyz="-1.75682286192042E-11 -0.0108820145632286 -0.00405362317350415" />
            <mass value="0.0134557296415635" />
            <inertia ixx="1.43307384392376E-06" ixy="-1.06834632214133E-14" ixz="-4.88547951587875E-15" iyy="3.88838933230828E-07" iyz="-4.1814613493025E-07" izz="1.33747540965672E-06" />
        </inertial>
        <visual>
            <origin rpy="0 0 0" xyz="0 0 0" />
            <geometry>
                <mesh filename="package://crt_ctag2f90c_gripper_visualization/meshes/Left_in_Link.STL" />
            </geometry>
            <material name="">
                <color rgba="0.976470588235294 0.866666666666667 0.784313725490196 1" />
            </material>
        </visual>
        <collision>
            <origin rpy="0 0 0" xyz="0 0 0" />
            <geometry>
                <mesh filename="package://crt_ctag2f90c_gripper_visualization/meshes/Left_in_Link.STL" />
            </geometry>
        </collision>
    </link>
    <joint name="Left_in_Joint" type="revolute">
        <origin rpy="0 0 0" xyz="0 0.023914 -0.0020253" />
        <parent link="Left_1_Link" />
        <child link="Left_in_Link" />
        <axis xyz="-1 0 0" />
        <limit effort="0" lower="-0.08" upper="-0.01" velocity="0" />
        <mimic joint="Left_1_Joint" multiplier="0.1" offset="0" />
    </joint>
    <link name="Left_up_Link">
        <inertial>
            <origin rpy="0 0 0" xyz="8.69802213948566E-11 0.0124078988097444 -0.0072525614743534" />
            <mass value="0.014692561982481" />
            <inertia ixx="2.35283034039115E-06" ixy="3.49796352982052E-14" ixz="-4.72158842036621E-15" iyy="5.8942945477579E-07" iyz="7.05860796345956E-07" izz="2.07228020361883E-06" />
        </inertial>
        <visual>
            <origin rpy="0 0 0" xyz="0 0 0" />
            <geometry>
                <mesh filename="package://crt_ctag2f90c_gripper_visualization/meshes/Left_up_Link.STL" />
            </geometry>
            <material name="">
                <color rgba="0.976470588235294 0.866666666666667 0.784313725490196 1" />
            </material>
        </visual>
        <collision>
            <origin rpy="0 0 0" xyz="0 0 0" />
            <geometry>
                <mesh filename="package://crt_ctag2f90c_gripper_visualization/meshes/Left_up_Link.STL" />
            </geometry>
        </collision>
    </link>
    <joint name="Left_up_Joint" type="revolute">
        <origin rpy="0 0 0" xyz="0 0.054804 -0.0046413" />
        <parent link="Left_1_Link" />
        <child link="Left_up_Link" />
        <axis xyz="-1 0 0" />
        <limit effort="2" lower="0.1" upper="0.8" velocity="1000" />
        <mimic joint="Left_1_Joint" multiplier="-1" offset="0" />
    </joint>
    <link name="Left_Pad_Link">
        <inertial>
            <origin rpy="0 0 0" xyz="-3.83777509579761E-08 0.00303135276101582 0.0028336970357949" />
            <mass value="0.0183171479595721" />
            <inertia ixx="2.35683098270332E-06" ixy="-4.7353365844279E-12" ixz="-9.31433971475514E-13" iyy="9.08136064346118E-07" iyz="-1.55873132053129E-08" izz="3.18448591439082E-06" />
        </inertial>
        <visual>
            <origin rpy="0 0 0" xyz="0 0 0" />
            <geometry>
                <mesh filename="package://crt_ctag2f90c_gripper_visualization/meshes/Left_Pad_Link.STL" />
            </geometry>
            <material name="">
                <color rgba="0.976470588235294 0.866666666666667 0.784313725490196 1" />
            </material>
        </visual>
        <collision>
            <origin rpy="0 0 0" xyz="0 0 0" />
            <geometry>
                <mesh filename="package://crt_ctag2f90c_gripper_visualization/meshes/Left_Pad_Link.STL" />
            </geometry>
        </collision>
    </link>
    <joint name="Left_Pad_Joint" type="fixed">
        <origin rpy="0 0 0" xyz="0 0.04125 -0.02425" />
        <parent link="Left_up_Link" />
        <child link="Left_Pad_Link" />
        <axis xyz="0 0 0" />
    </joint>
    <link name="Left_2_Link">
        <inertial>
            <origin rpy="0 0 0" xyz="5.08224485200288E-06 0.0327050710040551 -0.00276963392800038" />
            <mass value="0.0188752657753052" />
            <!--mass value="0.00001" /-->
            <inertia ixx="3.4145090175335E-06" ixy="-3.3317063785682E-22" ixz="-8.3582474326843E-22" iyy="2.86837057727488E-07" iyz="2.64809197911117E-07" izz="3.39111483394506E-06" />
            <!--inertia ixx="0" ixy="0" ixz="0" iyy="0" iyz="0" izz="0" /-->
        </inertial>
        <visual>
            <origin rpy="0 0 0" xyz="0 0 0" />
            <geometry>
                <mesh filename="package://crt_ctag2f90c_gripper_visualization/meshes/Left_2_Link.STL" />
            </geometry>
            <material name="">
                <color rgba="0.976470588235294 0.866666666666667 0.784313725490196 1" />
            </material>
        </visual>
        <collision>
            <origin rpy="0 0 0" xyz="0 0 0" />
            <geometry>
                <mesh filename="package://crt_ctag2f90c_gripper_visualization/meshes/Left_2_Link.STL" />
            </geometry>
        </collision>
    </link>
    <joint name="Left_2_Joint" type="revolute">
        <origin rpy="1.5708 0 0" xyz="0 -0.016 0.107" />
        <parent link="crt_base_link" />
        <child link="Left_2_Link" />
        <axis xyz="1 0 0" />
        <!--limit effort="2" lower="0.1" upper="0.8" velocity="1000" /-->
        <limit effort="0.5" lower="0.1" upper="0.8" velocity="0" />
        <mimic joint="Left_1_Joint" multiplier="-1" offset="0" />
    </joint>
    <link name="Right_2_Link">
        <inertial>
            <origin rpy="0 0 0" xyz="1.94651792710713E-17 0.0327174794493866 -0.00277053098700989" />
            <mass value="0.0188856364479881" />
            <!--mass value="0.000001" /-->
            <inertia ixx="3.41458781978465E-06" ixy="2.85152078238725E-22" ixz="9.8903086622122E-22" iyy="2.86883124998043E-07" iyz="2.64817198026894E-07" izz="3.39114800103702E-06" />
            <!--inertia ixx="0" ixy="0" ixz="0" iyy="0" iyz="0" izz="0" /-->
        </inertial>
        <visual>
            <origin rpy="0 0 0" xyz="0 0 0" />
            <geometry>
                <mesh filename="package://crt_ctag2f90c_gripper_visualization/meshes/Right_2_Link.STL" />
            </geometry>
            <material name="">
                <color rgba="0.976470588235294 0.866666666666667 0.784313725490196 1" />
            </material>
        </visual>
        <collision>
            <origin rpy="0 0 0" xyz="0 0 0" />
            <geometry>
                <mesh filename="package://crt_ctag2f90c_gripper_visualization/meshes/Right_2_Link.STL" />
            </geometry>
        </collision>
    </link>
    <joint name="Right_2_Joint" type="revolute">
        <origin rpy="1.5708 0 3.1416" xyz="0 0.016 0.107" />
        <parent link="crt_base_link" />
        <child link="Right_2_Link" />
        <axis xyz="-1 0 0" />
        <!--limit effort="2" lower="-0.8" upper="-0.1" velocity="1000" /-->
        <limit effort="0.5" lower="-0.8" upper="-0.1" velocity="0" />
        <mimic joint="Right_1_Joint" multiplier="1" offset="0" />
    </joint>
    <link name="Right_1_Link">
        <inertial>
            <origin rpy="0 0 0" xyz="-5.25233292439781E-19 0.0252734640095115 -0.00214040614650291" />
            <mass value="0.0129014357535444" />
            <inertia ixx="3.35976482443235E-06" ixy="-3.94978742494071E-23" ixz="-2.72484926002331E-23" iyy="1.65185846940368E-07" iyz="2.63476012977044E-07" izz="3.25394125032869E-06" />
        </inertial>
        <visual>
            <origin rpy="0 0 0" xyz="0 0 0" />
            <geometry>
                <mesh filename="package://crt_ctag2f90c_gripper_visualization/meshes/Right_1_Link.STL" />
            </geometry>
            <material name="">
                <color rgba="0.976470588235294 0.866666666666667 0.784313725490196 1" />
            </material>
        </visual>
        <collision>
            <origin rpy="0 0 0" xyz="0 0 0" />
            <geometry>
                <mesh filename="package://crt_ctag2f90c_gripper_visualization/meshes/Right_1_Link.STL" />
            </geometry>
        </collision>
    </link>
    <joint name="Right_1_Joint" type="revolute">
        <origin rpy="1.5708 0 3.1416" xyz="0 0.030141 0.090147" />
        <parent link="crt_base_link" />
        <child link="Right_1_Link" />
        <axis xyz="-1 0 0" />
        <limit effort="2" lower="-0.8" upper="-0.1" velocity="1000" />
        <mimic joint="Left_1_Joint" multiplier="1" offset="0" />
    </joint>
    <link name="Right_in_Link">
        <inertial>
            <origin rpy="0 0 0" xyz="-1.7568261982498E-11 -0.0108820145632292 -0.00405362317350229" />
            <mass value="0.0134557296415635" />
            <inertia ixx="1.43307384392376E-06" ixy="-1.06834687803419E-14" ixz="-4.88548199727378E-15" iyy="3.88838933230828E-07" iyz="-4.1814613493025E-07" izz="1.33747540965672E-06" />
        </inertial>
        <visual>
            <origin rpy="0 0 0" xyz="0 0 0" />
            <geometry>
                <mesh filename="package://crt_ctag2f90c_gripper_visualization/meshes/Right_in_Link.STL" />
            </geometry>
            <material name="">
                <color rgba="0.976470588235294 0.866666666666667 0.784313725490196 1" />
            </material>
        </visual>
        <collision>
            <origin rpy="0 0 0" xyz="0 0 0" />
            <geometry>
                <mesh filename="package://crt_ctag2f90c_gripper_visualization/meshes/Right_in_Link.STL" />
            </geometry>
        </collision>
    </link>
    <joint name="Right_in_Joint" type="revolute">
        <origin rpy="0 0 0" xyz="0 0.023914 -0.0020253" />
        <parent link="Right_1_Link" />
        <child link="Right_in_Link" />
        <axis xyz="-1 0 0" />
        <limit effort="0" lower="-0.08" upper="-0.01" velocity="0" />
        <mimic joint="Right_1_Joint" multiplier="0.1" offset="0" />
    </joint>
    <link name="Right_up_Link">
        <inertial>
            <origin rpy="0 0 0" xyz="8.69814518862609E-11 0.0124078988097266 -0.00725256147435587" />
            <mass value="0.014692561982481" />
            <inertia ixx="2.35283034039115E-06" ixy="3.49796366331572E-14" ixz="-4.72158801523363E-15" iyy="5.89429454773258E-07" iyz="7.05860796343296E-07" izz="2.07228020362137E-06" />
        </inertial>
        <visual>
            <origin rpy="0 0 0" xyz="0 0 0" />
            <geometry>
                <mesh filename="package://crt_ctag2f90c_gripper_visualization/meshes/Right_up_Link.STL" />
            </geometry>
            <material name="">
                <color rgba="0.976470588235294 0.866666666666667 0.784313725490196 1" />
            </material>
        </visual>
        <collision>
            <origin rpy="0 0 0" xyz="0 0 0" />
            <geometry>
                <mesh filename="package://crt_ctag2f90c_gripper_visualization/meshes/Right_up_Link.STL" />
            </geometry>
        </collision>
    </link>
    <joint name="Right_up_Joint" type="revolute">
        <origin rpy="0 0 0" xyz="0 0.054804 -0.0046413" />
        <parent link="Right_1_Link" />
        <child link="Right_up_Link" />
        <axis xyz="1 0 0" />
        <limit effort="2" lower="-0.8" upper="-0.1" velocity="1000" />
        <mimic joint="Right_1_Joint" multiplier="1" offset="0" />
    </joint>
    <link name="Right_Pad_Link">
        <inertial>
            <origin rpy="0 0 0" xyz="-3.83777500494227E-08 0.0030313527610159 0.00283369703564792" />
            <mass value="0.0366342959191441" />
            <inertia ixx="4.71366196540664E-06" ixy="-9.47067316877366E-12" ixz="-1.8628679404863E-12" iyy="1.81627212869223E-06" iyz="-3.11746264105278E-08" izz="6.36897182878164E-06" />
        </inertial>
        <visual>
            <origin rpy="0 0 0" xyz="0 0 0" />
            <geometry>
                <mesh filename="package://crt_ctag2f90c_gripper_visualization/meshes/Right_Pad_Link.STL" />
            </geometry>
            <material name="">
                <color rgba="0.976470588235294 0.866666666666667 0.784313725490196 1" />
            </material>
        </visual>
        <collision>
            <origin rpy="0 0 0" xyz="0 0 0" />
            <geometry>
                <mesh filename="package://crt_ctag2f90c_gripper_visualization/meshes/Right_Pad_Link.STL" />
            </geometry>
        </collision>
    </link>
    <joint name="Right_Pad_Joint" type="fixed">
        <origin rpy="0 0 0" xyz="0 0.04125 -0.02425" />
        <parent link="Right_up_Link" />
        <child link="Right_Pad_Link" />
        <axis xyz="0 0 0" />
    </joint>
    <transmission name="trans_Left_1_Joint">
        <type>transmission_interface/SimpleTransmission</type>
        <joint name="Left_1_Joint">
            <hardwareInterface>hardware_interface/PositionJointInterface</hardwareInterface>
        </joint>
        <actuator name="Left_1_Joint_motor">
            <hardwareInterface>hardware_interface/PositionJointInterface</hardwareInterface>
            <mechanicalReduction>1</mechanicalReduction>
        </actuator>
    </transmission>
    <gazebo>
        <plugin filename="libroboticsgroup_upatras_gazebo_mimic_joint_plugin.so" name="mimic_1">
            <joint>Left_1_Joint</joint>
            <mimicJoint>Left_in_Joint</mimicJoint>
            <multiplier>0.1</multiplier>
            <offset>0.0</offset>
            <maxEffort>5.0</maxEffort>
            <hasPID />
        </plugin>
        <plugin filename="libroboticsgroup_upatras_gazebo_mimic_joint_plugin.so" name="mimic_2">
            <joint>Left_1_Joint</joint>
            <mimicJoint>Left_up_Joint</mimicJoint>
            <multiplier>-1.0</multiplier>
            <offset>0.0</offset>
            <maxEffort>5.0</maxEffort>
            <hasPID />
        </plugin>
        <plugin filename="libroboticsgroup_upatras_gazebo_mimic_joint_plugin.so" name="mimic_3">
            <joint>Left_1_Joint</joint>
            <mimicJoint>Left_2_Joint</mimicJoint>
            <multiplier>-1.0</multiplier>
            <offset>0.0</offset>
            <maxEffort>5.0</maxEffort>
            <hasPID />
        </plugin>
        <plugin filename="libroboticsgroup_upatras_gazebo_mimic_joint_plugin.so" name="mimic_4">
            <joint>Right_1_Joint</joint>
            <mimicJoint>Right_2_Joint</mimicJoint>
            <multiplier>1.0</multiplier>
            <offset>0.0</offset>
            <maxEffort>5.0</maxEffort>
            <hasPID />
        </plugin>
        <plugin filename="libroboticsgroup_upatras_gazebo_mimic_joint_plugin.so" name="mimic_5">
            <joint>Left_1_Joint</joint>
            <mimicJoint>Right_1_Joint</mimicJoint>
            <multiplier>1.0</multiplier>
            <offset>0.0</offset>
            <maxEffort>5.0</maxEffort>
            <hasPID />
        </plugin>
        <plugin filename="libroboticsgroup_upatras_gazebo_mimic_joint_plugin.so" name="mimic_6">
            <joint>Right_1_Joint</joint>
            <mimicJoint>Right_in_Joint</mimicJoint>
            <multiplier>0.1</multiplier>
            <offset>0.0</offset>
            <maxEffort>5.0</maxEffort>
            <hasPID />
        </plugin>
        <plugin filename="libroboticsgroup_upatras_gazebo_mimic_joint_plugin.so" name="mimic_7">
            <joint>Right_1_Joint</joint>
            <mimicJoint>Right_up_Joint</mimicJoint>
            <multiplier>1.0</multiplier>
            <offset>0.0</offset>
            <maxEffort>5.0</maxEffort>
            <hasPID />
        </plugin>
        <plugin name="gazebo_ros_control" filename="libgazebo_ros_control.so">
            <robotNamespace>/</robotNamespace>
        </plugin>
    </gazebo>
    <gazebo>
        <plugin filename="libgazebo_grasp_fix.so" name="gazebo_grasp_fix">
            <arm>
                <arm_name>/my_gen3</arm_name>
                <palm_link>bracelet_link</palm_link>
                <gripper_link>Left_1_Link</gripper_link>
                <gripper_link>Right_1_Link</gripper_link>
                <gripper_link>Left_in_Link</gripper_link>
                <gripper_link>Right_in_Link</gripper_link>
                <gripper_link>Left_up_Link</gripper_link>
                <gripper_link>Right_up_Link</gripper_link>
                <gripper_link>Left_2_Link</gripper_link>
                <gripper_link>Right_2_Link</gripper_link>
            </arm>
            <forces_angle_tolerance>100</forces_angle_tolerance>
            <update_rate>100</update_rate>
            <grip_count_threshold>3</grip_count_threshold>
            <max_grip_count>10</max_grip_count>
            <release_tolerance>0.001</release_tolerance>
            <disable_collisions_on_attach>false</disable_collisions_on_attach>
            <contact_topic>__default_topic__</contact_topic>
        </plugin>
    </gazebo>
 <!--    <transmission name="trans_Left_in_Joint">
        <type>transmission_interface/SimpleTransmission</type>
        <joint name="Left_in_Joint">
            <hardwareInterface>hardware_interface/EffortJointInterface</hardwareInterface>
        </joint>
        <actuator name="Left_in_Joint_motor">
            <hardwareInterface>hardware_interface/EffortJointInterface</hardwareInterface>
            <mechanicalReduction>1</mechanicalReduction>
        </actuator>
    </transmission>
    <transmission name="trans_Left_up_Joint">
        <type>transmission_interface/SimpleTransmission</type>
        <joint name="Left_up_Joint">
            <hardwareInterface>hardware_interface/EffortJointInterface</hardwareInterface>
        </joint>
        <actuator name="Left_up_Joint_motor">
            <hardwareInterface>hardware_interface/EffortJointInterface</hardwareInterface>
            <mechanicalReduction>1</mechanicalReduction>
        </actuator>
    </transmission>
    <transmission name="trans_Left_2_Joint">
        <type>transmission_interface/SimpleTransmission</type>
        <joint name="Left_2_Joint">
            <hardwareInterface>hardware_interface/EffortJointInterface</hardwareInterface>
        </joint>
        <actuator name="Left_2_Joint_motor">
            <hardwareInterface>hardware_interface/EffortJointInterface</hardwareInterface>
            <mechanicalReduction>1</mechanicalReduction>
        </actuator>
    </transmission>
    <transmission name="trans_Right_2_Joint">
        <type>transmission_interface/SimpleTransmission</type>
        <joint name="Right_2_Joint">
            <hardwareInterface>hardware_interface/EffortJointInterface</hardwareInterface>
        </joint>
        <actuator name="Right_2_Joint_motor">
            <hardwareInterface>hardware_interface/EffortJointInterface</hardwareInterface>
            <mechanicalReduction>1</mechanicalReduction>
        </actuator>
    </transmission>
    <transmission name="trans_Right_1_Joint">
        <type>transmission_interface/SimpleTransmission</type>
        <joint name="Right_1_Joint">
            <hardwareInterface>hardware_interface/EffortJointInterface</hardwareInterface>
        </joint>
        <actuator name="Right_1_Joint_motor">
            <hardwareInterface>hardware_interface/EffortJointInterface</hardwareInterface>
            <mechanicalReduction>1</mechanicalReduction>
        </actuator>
    </transmission>
    <transmission name="trans_Right_in_Joint">
        <type>transmission_interface/SimpleTransmission</type>
        <joint name="Right_in_Joint">
            <hardwareInterface>hardware_interface/EffortJointInterface</hardwareInterface>
        </joint>
        <actuator name="Right_in_Joint_motor">
            <hardwareInterface>hardware_interface/EffortJointInterface</hardwareInterface>
            <mechanicalReduction>1</mechanicalReduction>
        </actuator>
    </transmission>
    <transmission name="trans_Right_up_Joint">
        <type>transmission_interface/SimpleTransmission</type>
        <joint name="Right_up_Joint">
            <hardwareInterface>hardware_interface/EffortJointInterface</hardwareInterface>
        </joint>
        <actuator name="Right_up_Joint_motor">
            <hardwareInterface>hardware_interface/EffortJointInterface</hardwareInterface>
            <mechanicalReduction>1</mechanicalReduction>
        </actuator>
    </transmission> -->
</robot>
